Workbook

Sheet README
B3: Bajaj Finance Ltd. - Strategic FP&A Dashboard
B5: 1. Project Objective
B6: Developed a Strategic FP&A Dashboard for Bajaj Finance Ltd. to analyze historical performance, forecast FY27–FY29 financials, and evaluate Bear, Base, and Bull scenarios for decision-making.
B8: 2. Tools Used
B9: Microsoft Excel
B10: Power BI
B11: DAX
B12: Financial Forecasting
B13: Scenario Analysis
B15: 3. Excel Work Performed
B16: Historical financial data compilation (FY23–FY26)
B17: Financial forecasting (FY27–FY29)
... B44: Prathamesh Rathod

Sheet Q4_FY26_Deep_Dive
B2: Section 1 — KPI Snapshot
B3: Metric | C3: Value | F3: Source: Bajaj Finance Q4 FY26 Investor Presentation.
B4: AUM | C4: 509975 | F4: All metrics represent consolidated Q4 FY26 performance unless otherwise stated.
B5: Disbursements (MM) | C5: 12.89
B6: Interest Income (₹ Cr) | C6: 19179 | F6: Key Observation
B7: NII (₹ Cr) | C7: 11781 | F7: 1. AUM crossed ₹5 lakh crore milestone
B8: PAT (₹ Cr) | C8: 5660 | F8: 2. ROE remained above 20%
B9: ROA (%) | C9: 0.047 | F9: 3. GNPA contained at 1.01%
B10: ROE (%) | C10: 0.2003 | F10: 4. Liquidity buffer remained strong at ₹15,020 Cr
B11: Customers (MM) | C11: 119.33 | F11: 5. PCR improved to 60%
B12: Branches (Count) | C12: 4098 | F12: 6. PAT grew 19% YoY to ₹5,660 Cr
B14: Section 2 — Profitability Analysis
B15: Metric | C15: Value
B16: Interest Income (₹ Cr) | C16: 19179
B17: Interest Expense (₹ Cr) | C17: 7398
B18: NII (₹ Cr) | C18: =C7 -> 11781
B19: NTI (₹ Cr) | C19: 14468
B20: Operating Expenses (₹ Cr) | C20: 4801
B21: PPOP (₹ Cr) | C21: 9667
B22: Loan Losses & Provisions (₹ Cr) | C22: 2125
B23: Share of Profit of Associates (₹ Cr) | C23: 10
B24: PBT (₹ Cr) | C24: 7552
B25: PAT (₹ Cr) | C25: =C8 -> 5660
B26: Cost-to-Income (%) | C26: 0.332
B27: Credit Cost (%) | C27: 0.0175
B28: ROA (%) | C28: =C9 -> 0.047
B29: ROE (%) | C29: =C10 -> 0.2003
B31: Section 3 — Risk Analysis
B32: Metric | C32: Value
B33: GNPA % | C33: 0.0101
B34: NNPA % | C34: 0.0041
B35: Provision Coverage % | C35: 0.6
B36: Credit Cost % | C36: 0.0175
B37: Stage 3 Assets % | C37: 0.0101
B39: Section 4 — Funding & Liquidity
B40: Metric | C40: Value
B41: Borrowings (₹ Cr) | C41: 428331
B42: Liquidity Buffer (₹ Cr) | C42: 15020
B43: Cost of Funds % | C43: 0.0741
B44: Capital Adequacy % | C44: 0.2155
...

Sheet Segment_Analysis
B2: Segment | C2: AUM (₹ Cr) | D2: % of Total AUM | E2: GNPA % | F2: NNPA % | G2: PCR % | H2: Strategic Observation | J2: Portfolio Highlights
B3: Captive 2W & 3W Finance | C3: 4288 | D3: =C3/$C$17 -> 0.0084082553 | E3: 0.1435 | F3: 0.0809 | G3: 0.47 | H3: Elevated stress segment requiring tighter credit monitoring. | J3: Largest Segment: Mortgages (31.78%)
B4: Open Market 2W & 3W Finance | C4: 8325 | D4: =C4/$C$17 -> 0.01632433 | E4: 0.0162 | F4: 0.009 | G4: 0.45 | H4: Stable growth with managed asset quality metrics. | J4: Fastest Scale Engine: Urban B2C Loans (20.49%)
B5: Urban Sales Finance | C5: 37430 | D5: =C5/$C$17 -> 0.073395755 | E5: 0.0042 | F5: 0.0006 | G5: 0.86 | H5: Strong asset quality supported by disciplined underwriting. | J5: Highest GNPA: Captive 2W & 3W (14.35%)
B6: Urban B2C Loans | C6: 104485 | D6: =C6/$C$17 -> 0.20488259 | E6: 0.0123 | F6: 0.0038 | G6: 0.69 | H6: Core volume engine; asset quality securely contained. | J6: Lowest GNPA: Loan Against Securities (0.02%)
B7: Rural Sales Finance | C7: 10559 | D7: =C7/$C$17 -> 0.020704937 | E7: 0.0039 | F7: 0.0005 | G7: 0.86 | H7: Clean expansion with negligible asset degradation. | J7: Strongest PCR: Rural B2C Loans (87%)
B8: Rural B2C Loans | C8: 25234 | D8: =C8/$C$17 -> 0.049480857 | E8: 0.0094 | F8: 0.0012 | G8: 0.87 | H8: Optimal risk-return profile with deep loss coverage. | J8: Highest Risk Watchlist: Captive 2W & 3W Finance
B9: MFI Lending | C9: 2198 | D9: =C9/$C$17 -> 0.0043100152 | E9: 0.0055 | F9: 0.001 | G9: 0.83 | H9: High-growth niche backed by robust risk provisions.
B10: Gold Loans | C10: 17831 | D10: =C10/$C$17 -> 0.034964459 | E10: 0.0033 | F10: 0.0031 | G10: 0.05 | H10: Collateral-backed portfolio with structurally lower credit risk.
B11: MSME Lending | C11: 51570 | D11: =C11/$C$17 -> 0.1011226 | E11: 0.0265 | F11: 0.01 | G11: 0.63 | H11: Elevated stress metrics indicate higher portfolio risk sensitivity.
B12: CV & Tractor Finance | C12: 3881 | D12: =C12/$C$17 -> 0.007610177 | E12: 0.0078 | F12: 0.0041 | G12: 0.48 | H12: Rapid low-base growth with well-contained defaults.
B13: Car Loans | C13: 15011 | D13: =C13/$C$17 -> 0.029434776 | E13: 0.0134 | F13: 0.0086 | G13: 0.36 | H13: Higher default trends; requires proactive monitoring focus.
B14: Commercial Lending | C14: 33839 | D14: =C14/$C$17 -> 0.066354233 | E14: 0.0008 | F14: 0.0004 | G14: 0.51 | H14: Pristine wholesale ledger providing strong group stability.
B15: Loan Against Securities | C15: 33247 | D15: =C15/$C$17 -> 0.065193392 | E15: 0.0002 | F15: 0.0001 | G15: 0.4 | H15: Secured capital market book with near-zero default risk.
B16: Mortgages | C16: 162077 | D16: =C16/$C$17 -> 0.31781362 | E16: 0.0054 | F16: 0.0028 | G16: 0.48 | H16: Primary balance sheet anchor with highly resilient metrics.
B17: Total Consolidated | C17: =SUM(C3:C16) -> 509975 | D17: =SUM(D3:D16) -> 1
B18: Source: Bajaj Finance Q4 FY26 Investor Presentation – Provisioning Coverage Consolidated Table (Page 66)

Sheet Historical_Trends
B2: Metric | C2: FY23 | D2: FY24 | E2: FY25 | F2: FY26 | G2: Trend / CAGR | I2: Notes
B3: Loans Booked (Mn) | C3: 29.6 | D3: 36.2 | E3: 43.4 | F3: 52.5 | G3: 0.211 | I3: 1. All currency figures are denominated uniformly in ₹ Crores. Volume thresholds are expressed in Millions (Mn).
B4: Customer Franchise (Mn) | C4: 69.1 | D4: 83.6 | E4: 101.8 | F4: 119.3 | G4: 0.2 | I4: 2. FY23–FY25 sourced from audited annual reports. FY26 sourced from Q4 FY26 investor presentation and audited financial results.
B5: AUM (₹ Cr) | C5: 247379 | D5: 330615 | E5: 416661 | F5: 509975 | G5: 0.273 | I5: 3. FY26 ROA and ROE are based on management-reported exit metrics disclosed in Q4 FY26 investor presentation.
B6: Total Income | C6: 41418 | D6: 54983 | E6: 69725 | F6: 82789 | G6: 0.26
B7: Interest Expenses | C7: 12560 | D7: 18725 | E7: 24771 | F7: 28666 | G7: 0.317 | I7: Key Historical Takeaways
B8: Net Total Income (NTI) | C8: 28858 | D8: 36258 | E8: 44954 | F8: 53324 | G8: 0.233 | I8: • AUM CAGR: 27.3%
B9: Operating Expenses | C9: 10142 | D9: 12325 | E9: 14296 | F9: 17776 | G9: 0.206 | I9: • PAT CAGR: 18.9%
B10: Loan Losses & Provisions | C10: 3190 | D10: 4631 | E10: 7966 | F10: 9482 | G10: 0.477 | I10: • Customer franchise CAGR: 20.0%
B11: Profit Before Tax (PBT) | C11: 15528 | D11: 19310 | E11: 22080 | F11: 25817 | G11: 0.185 | I11: • Asset quality remained stable with NNPA below 0.5%
B12: Profit After Tax (PAT) | C12: 11508 | D12: 14451 | E12: 16779 | F12: 19332 | G12: 0.189 | I12: • ROE moderated from 23.5% to 19.7%
B13: Opex to NTI % | C13: 0.351 | D13: 0.34 | E13: 0.332 | F13: 0.338
B14: Loan Loss to Avg AUF % | C14: 0.0147 | D14: 0.0163 | E14: 0.0217 | F14: 0.0227
B15: Return on Assets (ROA) % | C15: 0.053 | D15: 0.051 | E15: 0.046 | F15: 0.046
B16: Return on Equity (ROE) % | C16: 0.235 | D16: 0.221 | E16: 0.192 | F16: 0.197
B17: Net NPA % | C17: 0.0034 | D17: 0.0037 | E17: 0.0044 | F17: 0.0041
B18: Provisioning Coverage % | C18: 0.64 | D18: 0.57 | E18: 0.54 | F18: 0.6
B19: Capital Adequacy (CRAR) % | C19: 0.2497 | D19: 0.2252 | E19: 0.219 | F19: 0.2155
B20: Leverage Ratio | C20: 5.1 | D20: 4.9 | E20: 4.7 | F20: 4.8

Sheet Variance_Analysis
B2: Metric | C2: FY25 | D2: FY26 | E2: Variance | F2: Variance % | H2: Observation | I2: Commentary
B3: Loans Booked (Mn) | C3: 43.4 | D3: 52.5 | E3: =D3-C3 -> 9.1 | F3: =(D3-C3)/C3 -> 0.20967742 | H3: AUM Growth | I3: FY26 AUM increased 22.4% driven by strong customer additions and lending growth.
B4: Customer Franchise (Mn) | C4: 101.8 | D4: 119.3 | E4: =D4-C4 -> 17.5 | F4: =(D4-C4)/C4 -> 0.1719057 | H4: Profitability | I4: PAT grew despite higher funding costs and provisioning requirements.
B5: AUM (₹ Cr) | C5: 416661 | D5: 509975 | E5: =D5-C5 -> 93314 | F5: =(D5-C5)/C5 -> 0.22395665 | H5: Asset Quality | I5: Net NPA improved from FY25 levels despite rapid portfolio expansion.
B6: Total Income (₹ Cr) | C6: 69725 | D6: 82789 | E6: =D6-C6 -> 13064 | F6: =(D6-C6)/C6 -> 0.18736465 | H6: Capital Position | I6: Capital adequacy remained strong and comfortably above regulatory requirements.
B7: NTI (₹ Cr) | C7: 44954 | D7: 53324 | E7: =D7-C7 -> 8370 | F7: =(D7-C7)/C7 -> 0.18619033
B8: PAT (₹ Cr) | C8: 16779 | D8: 19332 | E8: =D8-C8 -> 2553 | F8: =(D8-C8)/C8 -> 0.15215448
B9: ROA (%) | C9: 0.046 | D9: 0.046 | E9: =D9-C9 -> 0 | F9: =(D9-C9)/C9 -> 0
B10: ROE (%) | C10: 0.192 | D10: 0.197 | E10: =D10-C10 -> 0.005 | F10: =(D10-C10)/C10 -> 0.026041667
B11: Net NPA (%) | C11: 0.0044 | D11: 0.0041 | E11: =D11-C11 -> -0.0003 | F11: =(D11-C11)/C11 -> -0.068181818
B12: Capital Adequacy (%) | C12: 0.219 | D12: 0.2155 | E12: =D12-C12 -> -0.0035 | F12: =(D12-C12)/C12 -> -0.015981735
B14: Metric | C14: Variance | D14: Primary Driver
B15: AUM | C15: +93,314 Cr | D15: Customer acquisition and loan growth
B16: Total Income | C16: +13,064 Cr | D16: Expansion of earning assets
B17: NTI | C17: +8,370 Cr | D17: Strong NII growth despite funding pressure
B18: PAT | C18: +2,553 Cr | D18: Scale benefits and operating leverage
B19: Net NPA | C19: -0.0003 | D19: Stable underwriting quality
B20: Capital Adequacy | C20: -0.0035 | D20: Growth consuming capital

Sheet Forecast_Model
B2: Metric | C2: FY23 | D2: FY24 | E2: FY25 | F2: FY26 | G2: FY27F | H2: FY28F | I2: FY29F | K2: Assumption | L2: FY27F | M2: FY28F | N2: FY29F
B3: Loans Booked | C3: =Historical_Trends!C3 -> 29.6 | D3: =Historical_Trends!D3 -> 36.2 | E3: =Historical_Trends!E3 -> 43.4 | F3: =Historical_Trends!F3 -> 52.5 | G3: =F3*(1+$L$3) -> 61.95 | H3: =G3*(1+$M$3) -> 72.4815 | I3: =H3*(1+$N$3) -> 84.07854 | K3: Loan Growth % | L3: 0.18 | M3: 0.17 | N3: 0.16
B4: Customer Franchise | C4: =Historical_Trends!C4 -> 69.1 | D4: =Historical_Trends!D4 -> 83.6 | E4: =Historical_Trends!E4 -> 101.8 | F4: =Historical_Trends!F4 -> 119.3 | G4: =F4*(1+L$4) -> 136.002 | H4: =G4*(1+M$4) -> 153.68226 | I4: =H4*(1+N$4) -> 172.12413 | K4: Customer Growth % | L4: 0.14 | M4: 0.13 | N4: 0.12
B5: AUM | C5: =Historical_Trends!C5 -> 247379 | D5: =Historical_Trends!D5 -> 330615 | E5: =Historical_Trends!E5 -> 416661 | F5: =Historical_Trends!F5 -> 509975 | G5: =F5*(1+L$5) -> 606870.25 | H5: =G5*(1+M$5) -> 716106.9 | I5: =H5*(1+N$5) -> 837845.07 | K5: AUM Growth % | L5: 0.19 | M5: 0.18 | N5: 0.17
B6: Interest Income | C6: =Historical_Trends!C6 -> 41418 | D6: =Historical_Trends!D6 -> 54983 | E6: =Historical_Trends!E6 -> 69725 | F6: =Historical_Trends!F6 -> 82789 | G6: =G$5*L$6 -> 89816.797 | H6: =H$5*M$6 -> 103835.5 | I6: =I$5*N$6 -> 118974 | K6: Interest Yield % | L6: 0.148 | M6: 0.145 | N6: 0.142
B7: Interest Expenses | C7: =Historical_Trends!C7 -> 12560 | D7: =Historical_Trends!D7 -> 18725 | E7: =Historical_Trends!E7 -> 24771 | F7: =Historical_Trends!F7 -> 28666 | G7: =G$5*L$7 -> 43694.658 | H7: =H$5*M$7 -> 50127.483 | I7: =I$5*N$7 -> 57811.31 | K7: Cost of Funds % | L7: 0.072 | M7: 0.07 | N7: 0.069
B8: NII | C8: =C6-C7 -> 28858 | D8: =D6-D7 -> 36258 | E8: =E6-E7 -> 44954 | F8: =F6-F7 -> 54123 | G8: =G6-G7 -> 46122.139 | H8: =H6-H7 -> 53708.017 | I8: =I6-I7 -> 61162.69 | K8: Opex to NTI % | L8: 0.335 | M8: 0.33 | N8: 0.325
B9: NTI | C9: =Historical_Trends!C8 -> 28858 | D9: =Historical_Trends!D8 -> 36258 | E9: =Historical_Trends!E8 -> 44954 | F9: =Historical_Trends!F8 -> 53324 | G9: =G8*1.21 -> 55807.788 | H9: =H8*1.21 -> 64986.701 | I9: =I8*1.21 -> 74006.855 | K9: Credit Cost % | L9: 0.019 | M9: 0.019 | N9: 0.018
B10: Operating Expenses | C10: =Historical_Trends!C9 -> 10142 | D10: =Historical_Trends!D9 -> 12325 | E10: =Historical_Trends!E9 -> 14296 | F10: =Historical_Trends!F9 -> 17776 | G10: =G$9*L$8 -> 18695.609 | H10: =H$9*M$8 -> 21445.611 | I10: =I$9*N$8 -> 24052.228 | K10: Tax Rate % | L10: 0.25 | M10: 0.25 | N10: 0.25
B11: Pre-Provision Operating Profit (PPOP) | C11: =C9-C10 -> 18716 | D11: =D9-D10 -> 23933 | E11: =E9-E10 -> 30658 | F11: =F9-F10 -> 35548 | G11: =G9-G10 -> 37112.179 | H11: =H9-H10 -> 43541.089 | I11: =I9-I10 -> 49954.627
B12: Loan Losses & Provisions | C12: =Historical_Trends!C10 -> 3190 | D12: =Historical_Trends!D10 -> 4631 | E12: =Historical_Trends!E10 -> 7966 | F12: =Historical_Trends!F10 -> 9482 | G12: =G5*L9 -> 11530.535 | H12: =H5*M9 -> 13606.031 | I12: =I5*N9 -> 15081.211 | K12: Assumption Notes
B13: PBT | C13: =Historical_Trends!C11 -> 15528 | D13: =Historical_Trends!D11 -> 19310 | E13: =Historical_Trends!E11 -> 22080 | F13: =Historical_Trends!F11 -> 25817 | G13: =G11-G12 -> 25581.644 | H13: =H11-H12 -> 29935.058 | I13: =I11-I12 -> 34873.416 | K13: 1. NTI modeled at 1.21x NII based on FY26 historical relationship
B14: PAT | C14: =Historical_Trends!C12 -> 11508 | D14: =Historical_Trends!D12 -> 14451 | E14: =Historical_Trends!E12 -> 16779 | F14: =Historical_Trends!F12 -> 19332 | G14: =G13*(1-L$10) -> 19186.233 | H14: =H13*(1-M$10) -> 22451.294 | I14: =I13*(1-N$10) -> 26155.062 | K14: 2. Interest income modeled using AUM × Yield approximation
B15: Opex to NTI % | C15: =Historical_Trends!C13 -> 0.351 | D15: =Historical_Trends!D13 -> 0.34 | E15: =Historical_Trends!E13 -> 0.332 | F15: =Historical_Trends!F13 -> 0.338 | G15: =G10/G9 -> 0.335 | H15: =H10/H9 -> 0.33 | I15: =I10/I9 -> 0.325 | K15: 3. Interest expense modeled using AUM × Cost of Funds approximation
B16: Loan Loss to Avg AUF % | C16: =Historical_Trends!C14 -> 0.0147 | D16: =Historical_Trends!D14 -> 0.0163 | E16: =Historical_Trends!E14 -> 0.0217 | F16: =Historical_Trends!F14 -> 0.0227 | G16: =G12/G5 -> 0.019 | H16: =H12/H5 -> 0.019 | I16: =I12/I5 -> 0.018 | K16: 4. Forecast assumes gradual moderation in growth and spreads
B17: ROA | C17: =Historical_Trends!C15 -> 0.053 | D17: =Historical_Trends!D15 -> 0.051 | E17: =Historical_Trends!E15 -> 0.046 | F17: 0.046 | G17: =G14/G5 -> 0.03161505 | H17: =H14/H5 -> 0.031351875 | I17: =I14/I5 -> 0.031217063 | K17: 5. Asset quality and capital metrics are based on management-guided assumptions.
B18: ROE | C18: =Historical_Trends!C16 -> 0.235 | D18: =Historical_Trends!D16 -> 0.221 | E18: =Historical_Trends!E16 -> 0.192 | F18: 0.197 | G18: =G14/(G5/G22) -> 0.15807525 | H18: =H14/(H5/H22) -> 0.16302975 | I18: =I14/(I5/I22) -> 0.16857214 | K18: 6. Net NPA % forecast reflects stable asset quality under continued high-growth lending environment
B19: Net NPA % | C19: =Historical_Trends!C17 -> 0.0034 | D19: =Historical_Trends!D17 -> 0.0037 | E19: =Historical_Trends!E17 -> 0.0044 | F19: =Historical_Trends!F17 -> 0.0041 | G19: 0.0042 | H19: 0.0043 | I19: 0.0044 | K19: 7. PCR assumptions reflect gradual strengthening of provisioning buffers and conservative risk management approach
B20: Provisioning Coverage % | C20: =Historical_Trends!C18 -> 0.64 | D20: =Historical_Trends!D18 -> 0.57 | E20: =Historical_Trends!E18 -> 0.54 | F20: =Historical_Trends!F18 -> 0.6 | G20: 0.61 | H20: 0.62 | I20: 0.63 | K20: 8. Capital adequacy forecast assumes internal accrual-led capital support without major external equity dilution
B21: Capital Adequacy | C21: =Historical_Trends!C19 -> 0.2497 | D21: =Historical_Trends!D19 -> 0.2252 | E21: =Historical_Trends!E19 -> 0.219 | F21: =Historical_Trends!F19 -> 0.2155 | G21: 0.21 | H21: 0.205 | I21: 0.2 | K21: 9. Leverage ratio forecast assumes balance sheet scaling supported through incremental borrowings and deposits
B22: Leverage Ratio | C22: =Historical_Trends!C20 -> 5.1 | D22: =Historical_Trends!D20 -> 4.9 | E22: =Historical_Trends!E20 -> 4.7 | F22: =Historical_Trends!F20 -> 4.8 | G22: 5 | H22: 5.2 | I22: 5.4

Sheet Scenario_Engine
B2: Assumption | C2: Bull | D2: Base | E2: Bear | G2: Notes:
B3: Loan Growth % | C3: 0.22 | D3: 0.18 | E3: 0.12 | G3: Bull and Bear scenarios represent sensitivity overlays derived from the Base Case forecast and are not independently integrated financial models.
B4: Customer Growth % | C4: 0.16 | D4: 0.14 | E4: 0.09
B5: AUM Growth % | C5: 0.22 | D5: 0.19 | E5: 0.13
B6: Interest Yield % | C6: 0.152 | D6: 0.148 | E6: 0.138
B7: Cost of Funds % | C7: 0.068 | D7: 0.072 | E7: 0.08
B8: Opex to NTI % | C8: 0.32 | D8: 0.335 | E8: 0.36
B9: Credit Cost % | C9: 0.016 | D9: 0.019 | E9: 0.026
B10: Tax Rate % | C10: 0.25 | D10: 0.25 | E10: 0.25
B12: Output Metric | C12: Bull | D12: Base | E12: Bear
B13: FY27 PAT | C13: =D13*1.12 -> 21488.581 | D13: =Forecast_Model!G14 -> 19186.233 | E13: =D13*0.82 -> 15732.711
B14: FY27 ROA | C14: =D14+0.35% -> 0.03511505 | D14: =Forecast_Model!G17 -> 0.03161505 | E14: =D14-0.45% -> 0.02711505
B15: FY27 ROE | C15: =D15+2% -> 0.17807525 | D15: =Forecast_Model!G18 -> 0.15807525 | E15: =D15-3% -> 0.12807525
B16: FY27 PBT | C16: =D16*1.1 -> 28139.809 | D16: =Forecast_Model!G13 -> 25581.644 | E16: =D16*0.84 -> 21488.581
B17: FY27 AUM | C17: =509975*(1+C5) -> 622169.5 | D17: =Forecast_Model!G5 -> 606870.25 | E17: =509975*(1+E5) -> 576271.75
B19: Metric | C19: Upside Impact
B20: PAT Impact | C20: 0.12
B21: PBT Impact | C21: 0.1
B22: AUM Impact | C22: 0.025
B24: Metric | C24: Downside Impact
B25: PAT Impact | C25: -0.18
B26: PBT Impact | C26: -0.16
B27: AUM Impact | C27: -0.05

Sheet Management_Insights
B3: Quarter | C3: Category | D3: Observation | E3: Business Impact | F3: Management Implication
B4: Q4 FY26 | C4: Growth | D4: AUM grew 22% YoY, crossing ₹5 lakh crore. | E4: Strong portfolio expansion supported income growth. | F4: Asset quality monitoring remains critical.
B5: Q4 FY26 | C5: Profitability | D5: Interest income growth remained strong despite elevated funding costs. | E5: Net interest income growth remained resilient despite funding cost pressure. | F5: Treasury and liability management efficiency will remain critical to protecting spreads and margins.
B6: Q4 FY26 | C6: Operating Efficiency | D6: Operating expenses grew alongside continued branch expansion and scaling activities. | E6: Cost-to-income ratio remained stable at 33.2%, indicating controlled operating leverage. | F6: Management appears to be balancing expansion with disciplined expense control.
B7: Q4 FY26 | C7: Credit Risk | D7: Credit cost remained controlled at 1.75% despite continued growth in lending activity. | E7: Stable asset quality supported profitability and return ratios. | F7: Credit underwriting discipline remains critical as unsecured lending exposure expands.
B8: Q4 FY26 | C8: Shareholder Returns | D8: ROE improved to 20.03%, reflecting strong profitability generation and efficient capital deployment. | E8: Higher return metrics strengthen investor confidence and valuation support. | F8: Sustaining ROE during balance sheet expansion remains a strategic priority
B10: • Strong balance sheet growth supported by customer acquisition.
B11: • Asset quality remained healthy despite rapid portfolio expansion.
B12: • Profitability remained resilient amid funding cost pressures.
B13: • Capital adequacy continues to provide room for future growth.

Sheet Dashboard_Data
B2: Executive KPI Table
B3: KPI | C3: Value
B4: AUM (₹ Cr) | C4: =Historical_Trends!F5 -> 509975
B5: Customers (Mn) | C5: =Historical_Trends!F4 -> 119.3
B6: PAT (₹ Cr) | C6: =Historical_Trends!F12 -> 19332
B7: ROA (%) | C7: =Historical_Trends!F15 -> 0.046
B8: ROE (%) | C8: =Historical_Trends!F16 -> 0.197
B9: Net NPA (%) | C9: =Historical_Trends!F17 -> 0.0041
B10: Capital Adequacy (%) | C10: =Historical_Trends!F19 -> 0.2155
B12: Historical Trend Table
B13: Year | C13: AUM | D13: PAT | E13: ROA | F13: ROE
B14: FY23 | C14: =Historical_Trends!C5 -> 247379 | D14: =Historical_Trends!C12 -> 11508 | E14: =Historical_Trends!C15 -> 0.053 | F14: =Historical_Trends!C16 -> 0.235
B15: FY24 | C15: =Historical_Trends!D5 -> 330615 | D15: =Historical_Trends!D12 -> 14451 | E15: =Historical_Trends!D15 -> 0.051 | F15: =Historical_Trends!D16 -> 0.221
B16: FY25 | C16: =Historical_Trends!E5 -> 416661 | D16: =Historical_Trends!E12 -> 16779 | E16: =Historical_Trends!E15 -> 0.046 | F16: =Historical_Trends!E16 -> 0.192
B17: FY26 | C17: =Historical_Trends!F5 -> 509975 | D17: =Historical_Trends!F12 -> 19332 | E17: =Historical_Trends!F15 -> 0.046 | F17: =Historical_Trends!F16 -> 0.197
B19: Forecast Table
B20: Year | C20: AUM | D20: PAT
B21: FY27F | C21: =Forecast_Model!G5 -> 606870.25 | D21: =Forecast_Model!G14 -> 19186.233
B22: FY28F | C22: =Forecast_Model!H5 -> 716106.9 | D22: =Forecast_Model!H14 -> 22451.294
B23: FY29F | C23: =Forecast_Model!I5 -> 837845.07 | D23: =Forecast_Model!I14 -> 26155.062
